Workbook

Sheet About
A1: TWYNTRUST FRAMEWORK · Quillfen Studio
A2: Starter Workbook — Gap Assessment, Roadmap, Crosswalk and Document Register
A3: The first file to open. Check where you stand against both standards, plan your route to certification, see how ISO/IEC 27001 and ISO/IEC 42001 line up clause by clause, and keep the list of every controlled document. Filled in for the sample company Quillfen Studio.
A5: Document ID | B5: IMS-WBK-001
A6: Version | B6: 2.0
A7: Prepared by | B7: Prof. Dr. Mohamed Fawzi Elgendi (Fawzooz), Fawzooz.ai
A8: License | B8: CC BY 4.0 — free to share and adapt, including commercially, with credit to Prof. Dr. Mohamed Fawzi Elgendi (Fawzooz), Fawzooz.ai · creativecommons.org/licenses/by/4.0
A9: Classification | B9: Internal
A10: Owner | B10: [Compliance Coordinator]
A11: Approved by | B11: [CEO] (Trust Council)
A12: Effective date | B12: 2026-11-01
A13: Kit folder | B13: 00 Start Here
A14: ISO/IEC 27001:2022 | B14: Clauses 4–10 (gap assessment); 7.5 (document register)
A15: ISO/IEC 42001:2023 | B15: Clauses 4–10 (gap assessment); 7.5 (document register)
A17: How to use this workbook
A18: • | B18: This is a SAMPLE filled in for the example company Quillfen Studio. Keep the structure, replace the example rows with your own.
A19: • | B19: Yellow cells are fill-in fields. Drop-down cells only accept the listed values.
A20: • | B20: Cells with formulas (scores, levels, due status) calculate automatically — do not type over them.
A21: • | B21: Start with 'Gap Assessment': clear the Status column and answer each question honestly for your organisation.
A22: • | B22: Then adapt 'Roadmap' — the 16–20 week plan suits a startup of 20–100 people with one part-time coordinator.
A23: • | B23: 'Crosswalk' shows why one system can serve both standards: only 6.1.4 and 8.4 are AI-only clauses.
A25: Sheets
A26: Gap Assessment | B26: Status: Done (2 points) · Partial (1) · Not started (0). The score and summary update automatically. 'Kit document' tells you which template helps close the gap.
A27: Gap Summary | B27: Percentage of maximum score per clause group.
A28: Roadmap | B28: Weeks are counted from kick-off. Strands follow the TWYNTRUST framework: 1 Ground, 2 Gauge, 3 Equip, 4 Operate, 5 Prove and improve.
A29: Crosswalk | B29: Both standards use the same harmonised structure, so one process can meet the same clause in both. Clause titles are short descriptions, not ISO text.
A30: Document Register | B30: Every controlled document and register in the system. Review status turns 'Overdue' after the next-review date.

Sheet Gap Assessment
A1: Readiness and gap assessment — both standards
A2: Status: Done (2 points) · Partial (1) · Not started (0). The score and summary update automatically. 'Kit document' tells you which template helps close the gap.
A4: Clause | B4: Applies to | C4: Question | D4: Kit document | E4: Status | F4: Score | G4: Notes / evidence | H4: Action owner
A5: 4.1 | B5: Both | C5: Have you written down the internal and external issues that affect your ability to protect information and use AI responsibly? | D5: IMS-REG-001 | E5: Done | F5: =IF(E5="Done",2,IF(E5="Partial",1,IF(E5="","",0))) | G5: Issues sheet reviewed Oct 2026
A6: 4.1 | B6: 42001 only | C6: Have you decided your role for each AI system (provider, producer, user/customer, partner)? | D6: IMS-REG-001 | E6: Done | F6: =IF(E6="Done",2,IF(E6="Partial",1,IF(E6="","",0))) | G6: AI Roles sheet
A7: 4.1 | B7: Both | C7: Have you considered whether climate change is a relevant issue? | D7: IMS-REG-001 | E7: Done | F7: =IF(E7="Done",2,IF(E7="Partial",1,IF(E7="","",0))) | G7: Low relevance; GPU energy tracked
A8: 4.2 | B8: Both | C8: Do you know your interested parties and which of their requirements you will meet (incl. legal and contractual)? | D8: IMS-REG-001 | E8: Done | F8: =IF(E8="Done",2,IF(E8="Partial",1,IF(E8="","",0)))
A9: 4.3 | B9: Both | C9: Is there a written scope with boundaries, interfaces and dependencies — and are any exclusions justified? | D9: IMS-REG-001 | E9: Done | F9: =IF(E9="Done",2,IF(E9="Partial",1,IF(E9="","",0))) | G9: One scope for both standards
A10: 4.4 | B10: Both | C10: Is the management system defined as a set of processes that interact (who, what, inputs, outputs)? | D10: IMS-MAN-001 | E10: Done | F10: =IF(E10="Done",2,IF(E10="Partial",1,IF(E10="","",0)))
A11: 5.1 | B11: Both | C11: Can top management show how they lead the system (resources, reviews, communication)? | D11: IMS-GOV-001 | E11: Done | F11: =IF(E11="Done",2,IF(E11="Partial",1,IF(E11="","",0))) | G11: Trust Council minutes
A12: 5.2 | B12: Both | C12: Is there an approved policy covering information security and AI, with the required commitments? | D12: IMS-POL-001 | E12: Done | F12: =IF(E12="Done",2,IF(E12="Partial",1,IF(E12="","",0)))
A13: 5.3 | B13: Both | C13: Are roles, responsibilities and authorities assigned and communicated (incl. who reports on performance)? | D13: IMS-GOV-001 | E13: Done | F13: =IF(E13="Done",2,IF(E13="Partial",1,IF(E13="","",0)))
A14: 6.1.1 | B14: Both | C14: Have you planned how to address risks and opportunities to the management system itself? | D14: IMS-PRO-001 | E14: Done | F14: =IF(E14="Done",2,IF(E14="Partial",1,IF(E14="","",0)))
A15: 6.1.2 | B15: Both | C15: Is there a documented, repeatable risk-assessment method with acceptance criteria — covering both security and AI risks? | D15: IMS-PRO-001 | E15: Done | F15: =IF(E15="Done",2,IF(E15="Partial",1,IF(E15="","",0)))
A16: 6.1.3 | B16: Both | C16: Is there a risk treatment plan, approved by risk owners, with residual risks accepted? | D16: IMS-REG-002 | E16: Partial | F16: =IF(E16="Done",2,IF(E16="Partial",1,IF(E16="","",0))) | G16: RSK-AI-005 accepted with expiry
A17: 6.1.3 | B17: 27001 only | C17: Is the ISO/IEC 27001 Statement of Applicability complete for all 93 Annex A controls? | D17: IMS-SOA-001 | E17: Done | F17: =IF(E17="Done",2,IF(E17="Partial",1,IF(E17="","",0)))
A18: 6.1.3 | B18: 42001 only | C18: Is the ISO/IEC 42001 Statement of Applicability complete for all 38 Annex A controls? | D18: IMS-SOA-002 | E18: Done | F18: =IF(E18="Done",2,IF(E18="Partial",1,IF(E18="","",0)))
A19: 6.1.4 | B19: 42001 only | C19: Is there a process for AI system impact assessments on individuals, groups and society? | D19: IMS-PRO-002 | E19: Done | F19: =IF(E19="Done",2,IF(E19="Partial",1,IF(E19="","",0)))
A20: 6.2 | B20: Both | C20: Are measurable objectives set, with plans saying what, who, resources, when and how results are evaluated? | D20: IMS-REG-003 | E20: Done | F20: =IF(E20="Done",2,IF(E20="Partial",1,IF(E20="","",0))) | G20: OBJ-01 to OBJ-07
A21: 6.3 | B21: Both | C21: Are changes to the management system planned in a controlled way? | D21: IMS-MAN-001 | E21: Done | F21: =IF(E21="Done",2,IF(E21="Partial",1,IF(E21="","",0)))
A22: 7.1 | B22: Both | C22: Have you provided the resources (people, budget, tools) the system needs? | D22: IMS-MAN-001 | E22: Done | F22: =IF(E22="Done",2,IF(E22="Partial",1,IF(E22="","",0)))
A23: 7.2 | B23: Both | C23: Is competence defined per role and evidenced (incl. AI skills)? | D23: IMS-REG-004 | E23: Partial | F23: =IF(E23="Done",2,IF(E23="Partial",1,IF(E23="","",0))) | G23: Contractor gap NC-2026-004
A24: 7.3 | B24: Both | C24: Is everyone aware of the policy, their contribution and what happens if they don't comply? | D24: IMS-PRO-003 | E24: Partial | F24: =IF(E24="Done",2,IF(E24="Partial",1,IF(E24="","",0))) | G24: AI-literacy module rolling out
A25: 7.4 | B25: Both | C25: Is internal and external communication planned (what, when, with whom, how)? | D25: IMS-REG-004 | E25: Done | F25: =IF(E25="Done",2,IF(E25="Partial",1,IF(E25="","",0)))
A26: 7.5 | B26: Both | C26: Is documented information created, approved, controlled and retained properly? | D26: IMS-PRO-004 | E26: Done | F26: =IF(E26="Done",2,IF(E26="Partial",1,IF(E26="","",0)))
A27: 8.1 | B27: Both | C27: Are operational processes planned and controlled, including outsourced processes? | D27: IMS-POL-002 | E27: Done | F27: =IF(E27="Done",2,IF(E27="Partial",1,IF(E27="","",0)))
A28: 8.1 | B28: 42001 only | C28: Do AI lifecycle processes follow responsible-development criteria with gates? | D28: IMS-POL-002 | E28: Done | F28: =IF(E28="Done",2,IF(E28="Partial",1,IF(E28="","",0))) | G28: AI Release Review
A29: 8.2 | B29: Both | C29: Are risk assessments repeated at planned intervals and after significant change? | D29: IMS-PRO-001 | E29: Done | F29: =IF(E29="Done",2,IF(E29="Partial",1,IF(E29="","",0)))
A30: 8.3 | B30: Both | C30: Is the risk treatment plan being implemented, with evidence? | D30: IMS-REG-002 | E30: Partial | F30: =IF(E30="Done",2,IF(E30="Partial",1,IF(E30="","",0))) | G30: 3 actions open
A31: 8.4 | B31: 42001 only | C31: Are AI system impact assessments performed and their results kept? | D31: IMS-PRO-002 | E31: Done | F31: =IF(E31="Done",2,IF(E31="Partial",1,IF(E31="","",0))) | G31: AIIA-2026-01, -02
A32: 9.1 | B32: Both | C32: Do you know what is monitored and measured, how, when, and who analyses the results? | D32: IMS-REG-003 | E32: Done | F32: =IF(E32="Done",2,IF(E32="Partial",1,IF(E32="","",0)))
A33: 9.2 | B33: Both | C33: Is there an internal audit programme and have audits been done by objective auditors? | D33: IMS-PRO-007 | E33: Done | F33: =IF(E33="Done",2,IF(E33="Partial",1,IF(E33="","",0))) | G33: AUD-2026-02
A34: 9.3 | B34: Both | C34: Has top management reviewed the system with all required inputs and recorded decisions? | D34: IMS-PRO-008 | E34: Done | F34: =IF(E34="Done",2,IF(E34="Partial",1,IF(E34="","",0))) | G34: Review 2026-10-21
A35: 10.1 | B35: Both | C35: Can you show continual improvement (improvement register, trend of metrics)? | D35: IMS-REG-008 | E35: Done | F35: =IF(E35="Done",2,IF(E35="Partial",1,IF(E35="","",0)))
A36: 10.2 | B36: Both | C36: Are nonconformities corrected, root causes found and corrective actions checked for effectiveness? | D36: IMS-PRO-009 | E36: Partial | F36: =IF(E36="Done",2,IF(E36="Partial",1,IF(E36="","",0))) | G36: CA-2026-004 open
A37: A (27001) | B37: 27001 only | C37: Are the controls you declared 'Implemented' actually working, with evidence an auditor can sample? | D37: IMS-SOA-001 | E37: Partial | F37: =IF(E37="Done",2,IF(E37="Partial",1,IF(E37="","",0))) | G37: 5 partially implemented
A38: A (42001) | B38: 42001 only | C38: Are AI controls (data provenance, V&V, monitoring, user information, suppliers) evidenced per system? | D38: IMS-SOA-002 | E38: Partial | F38: =IF(E38="Done",2,IF(E38="Partial",1,IF(E38="","",0))) | G38: A.6.2.6 fairness alerting planned
F39: =IF(E39="Done",2,IF(E39="Partial",1,IF(E39="","",0)))
F40: =IF(E40="Done",2,IF(E40="Partial",1,IF(E40="","",0)))
F41: =IF(E41="Done",2,IF(E41="Partial",1,IF(E41="","",0)))
...

Sheet Gap Summary
A1: Readiness by clause group
A2: Percentage of maximum score per clause group.
A4: Clause group | B4: Questions | C4: Score | D4: Max | E4: Readiness
A5: 4 Context | B5: =COUNTIFS('Gap Assessment'!A:A,"4*",'Gap Assessment'!E:E,"<>") | C5: =SUMIF('Gap Assessment'!A:A,"4*",'Gap Assessment'!F:F) | D5: =B5*2 | E5: =IF(D5=0,"",ROUND(C5/D5*100,0)&"%")
A6: 5 Leadership | B6: =COUNTIFS('Gap Assessment'!A:A,"5*",'Gap Assessment'!E:E,"<>") | C6: =SUMIF('Gap Assessment'!A:A,"5*",'Gap Assessment'!F:F) | D6: =B6*2 | E6: =IF(D6=0,"",ROUND(C6/D6*100,0)&"%")
A7: 6 Planning | B7: =COUNTIFS('Gap Assessment'!A:A,"6*",'Gap Assessment'!E:E,"<>") | C7: =SUMIF('Gap Assessment'!A:A,"6*",'Gap Assessment'!F:F) | D7: =B7*2 | E7: =IF(D7=0,"",ROUND(C7/D7*100,0)&"%")
A8: 7 Support | B8: =COUNTIFS('Gap Assessment'!A:A,"7*",'Gap Assessment'!E:E,"<>") | C8: =SUMIF('Gap Assessment'!A:A,"7*",'Gap Assessment'!F:F) | D8: =B8*2 | E8: =IF(D8=0,"",ROUND(C8/D8*100,0)&"%")
A9: 8 Operation | B9: =COUNTIFS('Gap Assessment'!A:A,"8*",'Gap Assessment'!E:E,"<>") | C9: =SUMIF('Gap Assessment'!A:A,"8*",'Gap Assessment'!F:F) | D9: =B9*2 | E9: =IF(D9=0,"",ROUND(C9/D9*100,0)&"%")
A10: 9 Performance evaluation | B10: =COUNTIFS('Gap Assessment'!A:A,"9*",'Gap Assessment'!E:E,"<>") | C10: =SUMIF('Gap Assessment'!A:A,"9*",'Gap Assessment'!F:F) | D10: =B10*2 | E10: =IF(D10=0,"",ROUND(C10/D10*100,0)&"%")
A11: 10 Improvement | B11: =COUNTIFS('Gap Assessment'!A:A,"10*",'Gap Assessment'!E:E,"<>") | C11: =SUMIF('Gap Assessment'!A:A,"10*",'Gap Assessment'!F:F) | D11: =B11*2 | E11: =IF(D11=0,"",ROUND(C11/D11*100,0)&"%")
A12: Annex A controls | B12: =COUNTIFS('Gap Assessment'!A:A,"A*",'Gap Assessment'!E:E,"<>") | C12: =SUMIF('Gap Assessment'!A:A,"A*",'Gap Assessment'!F:F) | D12: =B12*2 | E12: =IF(D12=0,"",ROUND(C12/D12*100,0)&"%")
A13: Overall | B13: =SUM(B5:B12) | C13: =SUM(C5:C12) | D13: =SUM(D5:D12) | E13: =IF(D13=0,"",ROUND(C13/D13*100,0)&"%")

Sheet Roadmap
A1: Implementation roadmap — startup route to two certificates
A2: Weeks are counted from kick-off. Strands follow the TWYNTRUST framework: 1 Ground, 2 Gauge, 3 Equip, 4 Operate, 5 Prove and improve.
A4: Week | B4: Strand | C4: Task | D4: Owner | E4: Output | F4: Status | G4: Done date
A5: 1 | B5: Start | C5: Get leadership commitment: agree why (contracts, trust), budget, and target certification date | D5: [CEO] | E5: Trust Council kick-off note | F5: Done
A6: 1 | B6: Start | C6: Appoint the Compliance Coordinator, ISMS owner and AIMS owner; set up a shared folder or wiki | D6: [CEO] | E6: IMS-GOV-001 draft | F6: Done
A7: 1–2 | B7: Start | C7: Run the gap assessment in this workbook; agree priorities | D7: [Compliance Coordinator] | E7: Gap Assessment sheet | F7: Done
A8: 2–3 | B8: 1 Ground | C8: Write context, interested parties, legal register and one scope for both standards | D8: [Compliance Coordinator] | E8: IMS-REG-001 | F8: Done
A9: 3 | B9: 1 Ground | C9: Agree governance: Trust Council, AI Release Review, RACI | D9: [CEO] | E9: IMS-GOV-001 | F9: Done
A10: 3–4 | B10: 1 Ground | C10: Write and approve the top-level policy | D10: [CEO] | E10: IMS-POL-001 | F10: Done
A11: 4 | B11: 4 Operate | C11: Build the asset and AI system inventory; name an owner for every AI system | D11: [Security Lead] | E11: IMS-REG-005 | F11: Done
A12: 4–5 | B12: 2 Gauge | C12: Agree the risk method and scales; train risk owners for one hour | D12: [Security Lead] | E12: IMS-PRO-001 | F12: Done
A13: 5–6 | B13: 2 Gauge | C13: Run risk workshops (security, then AI) and fill in the risk register | D13: [Security Lead] | E13: IMS-REG-002 | F13: Done
A14: 6–7 | B14: 2 Gauge | C14: Do impact assessments for High-criticality AI systems | D14: [Head of AI] | E14: IMS-PRO-002 | F14: Done
A15: 7–8 | B15: 2 Gauge | C15: Choose controls; complete both Statements of Applicability; approve treatment plan | D15: [Security Lead] | E15: IMS-SOA-001, IMS-SOA-002 | F15: Done
A16: 8 | B16: 2 Gauge | C16: Set objectives and metrics | D16: [Compliance Coordinator] | E16: IMS-REG-003 | F16: Done
... A26: 18–20 | B26: Certify | C26: Stage 2 audit (implementation and effectiveness) | D26: [Compliance Coordinator] | E26: Certificates | F26: Planned

Sheet Crosswalk
A1: Clause crosswalk — ISO/IEC 27001:2022 and ISO/IEC 42001:2023
A2: Both standards use the same harmonised structure, so one process can meet the same clause in both. Clause titles are short descriptions, not ISO text.
A4: Clause | B4: Topic | C4: ISO/IEC 27001 | D4: ISO/IEC 42001 | E4: What changes when AI is added
A5: 4.1 | B5: Organisation and its context | C5: Yes | D5: Yes | E5: 42001 also asks you to decide your AI role(s) and the intended purpose of your AI systems.
A6: 4.2 | B6: Interested parties | C6: Yes | D6: Yes | E6: Add people affected by AI outputs (e.g. depicted people, artists) even if they are not customers.
A7: 4.3 | B7: Scope | C7: Yes | D7: Yes | E7: Write one scope; list the AI systems in scope by name.
A8: 4.4 | B8: Management system | C8: Yes | D8: Yes | E8: Same.
A9: 5.1 | B9: Leadership and commitment | C9: Yes | D9: Yes | E9: Same; leaders also commit to responsible AI.
A10: 5.2 | B10: Policy | C10: Yes | D10: Yes | E10: AI policy must fit the purpose of AI use and give a framework for AI objectives — one combined policy works.
A11: 5.3 | B11: Roles, responsibilities, authorities | C11: Yes | D11: Yes | E11: Same.
A12: 6.1.1 | B12: Actions to address risks and opportunities | C12: Yes | D12: Yes | E12: 42001 asks you to separate tasks for AI risk assessment, treatment and impact assessment.
A13: 6.1.2 | B13: Risk assessment | C13: Yes (information security risk) | D13: Yes (AI risk) | E13: AI risks include consequences for individuals, groups and society, not only the organisation.
A14: 6.1.3 | B14: Risk treatment and SoA | C14: Yes — Annex A 93 controls | D14: Yes — Annex A 38 controls | E14: Two SoAs; one treatment plan.
A15: 6.1.4 | B15: AI system impact assessment | C15: — | D15: Yes | E15: New for AI: assess impacts on people and society; results feed risk assessment.
... A31: 10.2 | B31: Nonconformity and corrective action | C31: Yes | D31: Yes | E31: Same.

Sheet Document Register
A1: Master list of controlled documents
A2: Every controlled document and register in the system. Review status turns 'Overdue' after the next-review date.
A4: ID | B4: Title | C4: Folder | D4: Type | E4: Owner | F4: Version | G4: Status | H4: Effective | I4: Next review | J4: Review status
A5: IMS-GDE-001 | B5: Start Here — Build Your ISMS and AIMS with TWYNTRUST | C5: 00 Start Here | D5: docx | E5: [Compliance Coordinator] | F5: 2.0 | G5: Approved | H5: 2026-11-01 | I5: 2027-11-01 | J5: =IF(I5="","",IF(DATEVALUE(I5)<TODAY(),"Overdue","On track"))
A6: IMS-WBK-001 | B6: Starter Workbook — Gap Assessment, Roadmap, Crosswalk and Document Register | C6: 00 Start Here | D6: xlsx | E6: [Compliance Coordinator] | F6: 2.0 | G6: Approved | H6: 2026-11-01 | I6: 2027-11-01 | J6: =IF(I6="","",IF(DATEVALUE(I6)<TODAY(),"Overdue","On track"))
A7: IMS-MAN-001 | B7: Integrated Management System Manual (ISMS + AIMS) | C7: 01 Ground - Context and Leadership | D7: docx | E7: [CEO] | F7: 2.0 | G7: Approved | H7: 2026-11-01 | I7: 2027-11-01 | J7: =IF(I7="","",IF(DATEVALUE(I7)<TODAY(),"Overdue","On track"))
A8: IMS-REG-001 | B8: Context, Interested Parties and Scope Register | C8: 01 Ground - Context and Leadership | D8: xlsx | E8: [Compliance Coordinator] | F8: 2.0 | G8: Approved | H8: 2026-11-01 | I8: 2027-11-01 | J8: =IF(I8="","",IF(DATEVALUE(I8)<TODAY(),"Overdue","On track"))
A9: IMS-POL-001 | B9: Information Security and Responsible AI Policy | C9: 01 Ground - Context and Leadership | D9: docx | E9: [CEO] | F9: 2.0 | G9: Approved | H9: 2026-11-01 | I9: 2027-11-01 | J9: =IF(I9="","",IF(DATEVALUE(I9)<TODAY(),"Overdue","On track"))
A10: IMS-GOV-001 | B10: Governance Charter, Roles and Responsibilities | C10: 01 Ground - Context and Leadership | D10: docx | E10: [CEO] | F10: 2.0 | G10: Approved | H10: 2026-11-01 | I10: 2027-11-01 | J10: =IF(I10="","",IF(DATEVALUE(I10)<TODAY(),"Overdue","On track"))
A11: IMS-PRO-001 | B11: Risk Management Methodology (Information Security and AI) | C11: 02 Gauge - Risk and Planning | D11: docx | E11: [Security Lead] | F11: 2.0 | G11: Approved | H11: 2026-11-01 | I11: 2027-11-01 | J11: =IF(I11="","",IF(DATEVALUE(I11)<TODAY(),"Overdue","On track"))
A12: IMS-REG-002 | B12: Integrated Risk Register and Treatment Plan | C12: 02 Gauge - Risk and Planning | D12: xlsx | E12: [Security Lead] | F12: 2.0 | G12: Approved | H12: 2026-11-01 | I12: 2027-11-01 | J12: =IF(I12="","",IF(DATEVALUE(I12)<TODAY(),"Overdue","On track"))
A13: IMS-PRO-002 | B13: AI System Impact Assessment Procedure and Worked Example | C13: 02 Gauge - Risk and Planning | D13: docx | E13: [Head of AI] | F13: 2.0 | G13: Approved | H13: 2026-11-01 | I13: 2027-11-01 | J13: =IF(I13="","",IF(DATEVALUE(I13)<TODAY(),"Overdue","On track"))
A14: IMS-SOA-001 | B14: Statement of Applicability — ISO/IEC 27001:2022 Annex A | C14: 02 Gauge - Risk and Planning | D14: xlsx | E14: [Security Lead] | F14: 2.0 | G14: Approved | H14: 2026-11-01 | I14: 2027-11-01 | J14: =IF(I14="","",IF(DATEVALUE(I14)<TODAY(),"Overdue","On track"))
A15: IMS-SOA-002 | B15: Statement of Applicability — ISO/IEC 42001:2023 Annex A | C15: 02 Gauge - Risk and Planning | D15: xlsx | E15: [Head of AI] | F15: 2.0 | G15: Approved | H15: 2026-11-01 | I15: 2027-11-01 | J15: =IF(I15="","",IF(DATEVALUE(I15)<TODAY(),"Overdue","On track"))
A16: IMS-REG-003 | B16: Objectives, Metrics and Monitoring Plan | C16: 02 Gauge - Risk and Planning | D16: xlsx | E16: [Compliance Coordinator] | F16: 2.0 | G16: Approved | H16: 2026-11-01 | I16: 2027-11-01 | J16: =IF(I16="","",IF(DATEVALUE(I16)<TODAY(),"Overdue","On track"))
... A33: IMS-REG-008 | B33: Nonconformity, Corrective Action and Improvement Log | C33: 05 Prove and Improve | D33: xlsx | E33: [Compliance Coordinator] | F33: 2.0 | G33: Approved | H33: 2026-11-01 | I33: 2027-11-01 | J33: =IF(I33="","",IF(DATEVALUE(I33)<TODAY(),"Overdue","On track"))
J34: =IF(I34="","",IF(DATEVALUE(I34)<TODAY(),"Overdue","On track"))
J35: =IF(I35="","",IF(DATEVALUE(I35)<TODAY(),"Overdue","On track"))
J36: =IF(I36="","",IF(DATEVALUE(I36)<TODAY(),"Overdue","On track"))
J37: =IF(I37="","",IF(DATEVALUE(I37)<TODAY(),"Overdue","On track"))
J38: =IF(I38="","",IF(DATEVALUE(I38)<TODAY(),"Overdue","On track"))
J39: =IF(I39="","",IF(DATEVALUE(I39)<TODAY(),"Overdue","On track"))
J40: =IF(I40="","",IF(DATEVALUE(I40)<TODAY(),"Overdue","On track"))
J41: =IF(I41="","",IF(DATEVALUE(I41)<TODAY(),"Overdue","On track"))
J42: =IF(I42="","",IF(DATEVALUE(I42)<TODAY(),"Overdue","On track"))
J43: =IF(I43="","",IF(DATEVALUE(I43)<TODAY(),"Overdue","On track"))
J44: =IF(I44="","",IF(DATEVALUE(I44)<TODAY(),"Overdue","On track"))
J45: =IF(I45="","",IF(DATEVALUE(I45)<TODAY(),"Overdue","On track"))
... J48: =IF(I48="","",IF(DATEVALUE(I48)<TODAY(),"Overdue","On track"))
